root - INFO - Бот запускается
2019-09-07 18:52:41,510 - INFO - Бот запускается
2019-09-07 18:53:48,484 - INFO - Бот запускается
2019-09-07 18:53:55,719 - INFO - Send email to the customer
2019-09-07 18:59:59,949 - INFO - Бот запускается
2019-09-07 19:00:15,205 - INFO - Send answer to the client
2019-09-07 19:01:55,190 - INFO - Бот запускается
2019-09-07 19:02:00,518 - ERROR - No error handlers are registered, logging exception.
Traceback (most recent call last):
  File "C:\Program Files\Python37\lib\site-packages\telegram\ext\dispatcher.py", line 372, in process_update
    handler.handle_update(update, self, check, context)
  File "C:\Program Files\Python37\lib\site-packages\telegram\ext\handler.py", line 120, in handle_update
    return self.callback(dispatcher.bot, update, **optional_args)
  File "C:/Users/Philipesko/PycharmProjects/LearningPython14/megabot/bot.py", line 17, in talk_to_me
    update.message.reply_text(user_text)
  File "C:\Program Files\Python37\lib\site-packages\telegram\message.py", line 478, in reply_text
    return self.bot.send_message(self.chat_id, *args, **kwargs)
  File "C:\Program Files\Python37\lib\site-packages\telegram\bot.py", line 66, in decorator
    result = func(self, *args, **kwargs)
  File "C:\Program Files\Python37\lib\site-packages\telegram\bot.py", line 258, in send_message
    timeout=timeout, **kwargs)
  File "C:\Program Files\Python37\lib\site-packages\telegram\bot.py", line 123, in _message
    result = self._request.post(url, data, timeout=timeout)
  File "C:\Program Files\Python37\lib\site-packages\telegram\utils\request.py", line 325, in post
    body=json.dumps(data).encode('utf-8'),
  File "C:\Program Files\Python37\lib\json\__init__.py", line 231, in dumps
    return _default_encoder.encode(obj)
  File "C:\Program Files\Python37\lib\json\encoder.py", line 199, in encode
    chunks = self.iterencode(o, _one_shot=True)
  File "C:\Program Files\Python37\lib\json\encoder.py", line 257, in iterencode
    return _iterencode(o, 0)
  File "C:\Program Files\Python37\lib\json\encoder.py", line 179, in default
    raise TypeError(f'Object of type {o.__class__.__name__} '
TypeError: Object of type method is not JSON serializable
2019-09-07 19:02:06,887 - ERROR - No error handlers are registered, logging exception.
Traceback (most recent call last):
  File "C:\Program Files\Python37\lib\site-packages\telegram\ext\dispatcher.py", line 372, in process_update
    handler.handle_update(update, self, check, context)
  File "C:\Program Files\Python37\lib\site-packages\telegram\ext\handler.py", line 120, in handle_update
    return self.callback(dispatcher.bot, update, **optional_args)
  File "C:/Users/Philipesko/PycharmProjects/LearningPython14/megabot/bot.py", line 17, in talk_to_me
    update.message.reply_text(user_text)
  File "C:\Program Files\Python37\lib\site-packages\telegram\message.py", line 478, in reply_text
    return self.bot.send_message(self.chat_id, *args, **kwargs)
  File "C:\Program Files\Python37\lib\site-packages\telegram\bot.py", line 66, in decorator
    result = func(self, *args, **kwargs)
  File "C:\Program Files\Python37\lib\site-packages\telegram\bot.py", line 258, in send_message
    timeout=timeout, **kwargs)
  File "C:\Program Files\Python37\lib\site-packages\telegram\bot.py", line 123, in _message
    result = self._request.post(url, data, timeout=timeout)
  File "C:\Program Files\Python37\lib\site-packages\telegram\utils\request.py", line 325, in post
    body=json.dumps(data).encode('utf-8'),
  File "C:\Program Files\Python37\lib\json\__init__.py", line 231, in dumps
    return _default_encoder.encode(obj)
  File "C:\Program Files\Python37\lib\json\encoder.py", line 199, in encode
    chunks = self.iterencode(o, _one_shot=True)
  File "C:\Program Files\Python37\lib\json\encoder.py", line 257, in iterencode
    return _iterencode(o, 0)
  File "C:\Program Files\Python37\lib\json\encoder.py", line 179, in default
    raise TypeError(f'Object of type {o.__class__.__name__} '
TypeError: Object of type method is not JSON serializable
2019-09-07 19:02:36,832 - INFO - Send answer to the client
2019-09-07 19:02:38,893 - ERROR - No error handlers are registered, logging exception.
Traceback (most recent call last):
  File "C:\Program Files\Python37\lib\site-packages\telegram\ext\dispatcher.py", line 372, in process_update
    handler.handle_update(update, self, check, context)
  File "C:\Program Files\Python37\lib\site-packages\telegram\ext\handler.py", line 120, in handle_update
    return self.callback(dispatcher.bot, update, **optional_args)
  File "C:/Users/Philipesko/PycharmProjects/LearningPython14/megabot/bot.py", line 17, in talk_to_me
    update.message.reply_text(user_text)
  File "C:\Program Files\Python37\lib\site-packages\telegram\message.py", line 478, in reply_text
    return self.bot.send_message(self.chat_id, *args, **kwargs)
  File "C:\Program Files\Python37\lib\site-packages\telegram\bot.py", line 66, in decorator
    result = func(self, *args, **kwargs)
  File "C:\Program Files\Python37\lib\site-packages\telegram\bot.py", line 258, in send_message
    timeout=timeout, **kwargs)
  File "C:\Program Files\Python37\lib\site-packages\telegram\bot.py", line 123, in _message
    result = self._request.post(url, data, timeout=timeout)
  File "C:\Program Files\Python37\lib\site-packages\telegram\utils\request.py", line 325, in post
    body=json.dumps(data).encode('utf-8'),
  File "C:\Program Files\Python37\lib\json\__init__.py", line 231, in dumps
    return _default_encoder.encode(obj)
  File "C:\Program Files\Python37\lib\json\encoder.py", line 199, in encode
    chunks = self.iterencode(o, _one_shot=True)
  File "C:\Program Files\Python37\lib\json\encoder.py", line 257, in iterencode
    return _iterencode(o, 0)
  File "C:\Program Files\Python37\lib\json\encoder.py", line 179, in default
    raise TypeError(f'Object of type {o.__class__.__name__} '
TypeError: Object of type method is not JSON serializable
2019-09-07 19:03:24,076 - INFO - Бот запускается
2019-09-07 19:03:31,500 - INFO - Receive message text from client:привет
2019-09-07 19:03:35,355 - INFO - Send answer to the client
2019-09-07 19:06:06,872 - INFO - Бот запускается
2019-09-07 19:06:14,096 - INFO - Receive message text from client:привет.
<<<<<<< Updated upstream
=======
2019-09-08 17:02:33,379 - INFO - Send answer to the client
2019-09-08 17:02:34,051 - INFO - Send answer to the client
2019-09-08 17:02:34,864 - INFO - Send answer to the client
2019-09-08 17:02:36,074 - INFO - Receive message text from client:  a,sh
2019-09-08 17:03:11,484 - WARNING - Retrying (Retry(total=2, connect=None, read=None, redirect=None)) after connection broken by 'ConnectTimeoutError(<telegram.vendor.ptb_urllib3.urllib3.contrib.socks.SOCKSHTTPSConnection object at 0x000001759768C1C8>, 'Connection to api.telegram.org timed out. (connect timeout=5.0)')': /bot812960937:AAEXGUPi7Au90FxLNA0_Y947goTAzbXNS3A/getUpdates
2019-09-08 17:04:07,325 - ERROR - No error handlers are registered, logging exception.
Traceback (most recent call last):
  File "C:\Users\philippn\AppData\Local\Programs\Python\Python37\lib\site-packages\telegram\ext\dispatcher.py", line 372, in process_update
    handler.handle_update(update, self, check, context)
  File "C:\Users\philippn\AppData\Local\Programs\Python\Python37\lib\site-packages\telegram\ext\handler.py", line 117, in handle_update
    return self.callback(update, context)
  File "C:/Users/philippn/PycharmProjects/LearningPython14/megabot/bot.py", line 15, in talk_to_me
    user_text = update.message.text
AttributeError: 'CallbackContext' object has no attribute 'message'
2019-09-08 17:04:20,381 - ERROR - No error handlers are registered, logging exception.
Traceback (most recent call last):
  File "C:\Users\philippn\AppData\Local\Programs\Python\Python37\lib\site-packages\telegram\ext\dispatcher.py", line 372, in process_update
    handler.handle_update(update, self, check, context)
  File "C:\Users\philippn\AppData\Local\Programs\Python\Python37\lib\site-packages\telegram\ext\handler.py", line 117, in handle_update
    return self.callback(update, context)
  File "C:/Users/philippn/PycharmProjects/LearningPython14/megabot/bot.py", line 11, in greet_user
    update.message.reply_text(text)
AttributeError: 'CallbackContext' object has no attribute 'message'
2019-09-08 17:05:32,130 - ERROR - No error handlers are registered, logging exception.
Traceback (most recent call last):
  File "C:\Users\philippn\AppData\Local\Programs\Python\Python37\lib\site-packages\telegram\ext\dispatcher.py", line 372, in process_update
    handler.handle_update(update, self, check, context)
  File "C:\Users\philippn\AppData\Local\Programs\Python\Python37\lib\site-packages\telegram\ext\handler.py", line 117, in handle_update
    return self.callback(update, context)
  File "C:/Users/philippn/PycharmProjects/LearningPython14/megabot/bot.py", line 11, in greet_user
    update.message.reply_text(text)
AttributeError: 'CallbackContext' object has no attribute 'message'
2019-09-08 17:05:52,338 - ERROR - No error handlers are registered, logging exception.
Traceback (most recent call last):
  File "C:\Users\philippn\AppData\Local\Programs\Python\Python37\lib\site-packages\telegram\ext\dispatcher.py", line 372, in process_update
    handler.handle_update(update, self, check, context)
  File "C:\Users\philippn\AppData\Local\Programs\Python\Python37\lib\site-packages\telegram\ext\handler.py", line 117, in handle_update
    return self.callback(update, context)
  File "C:/Users/philippn/PycharmProjects/LearningPython14/megabot/bot.py", line 15, in talk_to_me
    user_text = update.message.text
AttributeError: 'CallbackContext' object has no attribute 'message'
2019-09-08 17:17:53,012 - ERROR - No error handlers are registered, logging exception.
Traceback (most recent call last):
  File "C:\Users\philippn\AppData\Local\Programs\Python\Python37\lib\site-packages\telegram\ext\dispatcher.py", line 372, in process_update
    handler.handle_update(update, self, check, context)
  File "C:\Users\philippn\AppData\Local\Programs\Python\Python37\lib\site-packages\telegram\ext\handler.py", line 117, in handle_update
    return self.callback(update, context)
  File "C:/Users/philippn/PycharmProjects/LearningPython14/megabot/bot.py", line 15, in talk_to_me
    user_text = update.message.text
AttributeError: 'CallbackContext' object has no attribute 'message'
2019-09-08 17:17:59,071 - ERROR - No error handlers are registered, logging exception.
Traceback (most recent call last):
  File "C:\Users\philippn\AppData\Local\Programs\Python\Python37\lib\site-packages\telegram\ext\dispatcher.py", line 372, in process_update
    handler.handle_update(update, self, check, context)
  File "C:\Users\philippn\AppData\Local\Programs\Python\Python37\lib\site-packages\telegram\ext\handler.py", line 117, in handle_update
    return self.callback(update, context)
  File "C:/Users/philippn/PycharmProjects/LearningPython14/megabot/bot.py", line 15, in talk_to_me
    user_text = update.message.text
AttributeError: 'CallbackContext' object has no attribute 'message'
2019-09-08 17:18:07,385 - ERROR - No error handlers are registered, logging exception.
Traceback (most recent call last):
  File "C:\Users\philippn\AppData\Local\Programs\Python\Python37\lib\site-packages\telegram\ext\dispatcher.py", line 372, in process_update
    handler.handle_update(update, self, check, context)
  File "C:\Users\philippn\AppData\Local\Programs\Python\Python37\lib\site-packages\telegram\ext\handler.py", line 117, in handle_update
    return self.callback(update, context)
  File "C:/Users/philippn/PycharmProjects/LearningPython14/megabot/bot.py", line 11, in greet_user
    update.message.reply_text(text)
AttributeError: 'CallbackContext' object has no attribute 'message'
2019-09-08 17:18:17,490 - ERROR - No error handlers are registered, logging exception.
Traceback (most recent call last):
  File "C:\Users\philippn\AppData\Local\Programs\Python\Python37\lib\site-packages\telegram\ext\dispatcher.py", line 372, in process_update
    handler.handle_update(update, self, check, context)
  File "C:\Users\philippn\AppData\Local\Programs\Python\Python37\lib\site-packages\telegram\ext\handler.py", line 117, in handle_update
    return self.callback(update, context)
  File "C:/Users/philippn/PycharmProjects/LearningPython14/megabot/bot.py", line 15, in talk_to_me
    user_text = update.message.text
AttributeError: 'CallbackContext' object has no attribute 'message'
2019-09-08 17:18:26,027 - ERROR - No error handlers are registered, logging exception.
Traceback (most recent call last):
  File "C:\Users\philippn\AppData\Local\Programs\Python\Python37\lib\site-packages\telegram\ext\dispatcher.py", line 372, in process_update
    handler.handle_update(update, self, check, context)
  File "C:\Users\philippn\AppData\Local\Programs\Python\Python37\lib\site-packages\telegram\ext\handler.py", line 117, in handle_update
    return self.callback(update, context)
  File "C:/Users/philippn/PycharmProjects/LearningPython14/megabot/bot.py", line 11, in greet_user
    update.message.reply_text(text)
AttributeError: 'CallbackContext' object has no attribute 'message'
>>>>>>> Stashed changes
