root - INFO - Бот запускается
2019-09-07 18:52:41,510 - INFO - Бот запускается
2019-09-07 18:53:48,484 - INFO - Бот запускается
2019-09-07 18:53:55,719 - INFO - Send email to the customer
2019-09-07 18:59:59,949 - INFO - Бот запускается
2019-09-07 19:00:15,205 - INFO - Send answer to the client
2019-09-07 19:01:55,190 - INFO - Бот запускается
2019-09-07 19:02:00,518 - ERROR - No error handlers are registered, logging exception.
Traceback (most recent call last):
  File "C:\Program Files\Python37\lib\site-packages\telegram\ext\dispatcher.py", line 372, in process_update
    handler.handle_update(update, self, check, context)
  File "C:\Program Files\Python37\lib\site-packages\telegram\ext\handler.py", line 120, in handle_update
    return self.callback(dispatcher.bot, update, **optional_args)
  File "C:/Users/Philipesko/PycharmProjects/LearningPython14/megabot/bot.py", line 17, in talk_to_me
    update.message.reply_text(user_text)
  File "C:\Program Files\Python37\lib\site-packages\telegram\message.py", line 478, in reply_text
    return self.bot.send_message(self.chat_id, *args, **kwargs)
  File "C:\Program Files\Python37\lib\site-packages\telegram\bot.py", line 66, in decorator
    result = func(self, *args, **kwargs)
  File "C:\Program Files\Python37\lib\site-packages\telegram\bot.py", line 258, in send_message
    timeout=timeout, **kwargs)
  File "C:\Program Files\Python37\lib\site-packages\telegram\bot.py", line 123, in _message
    result = self._request.post(url, data, timeout=timeout)
  File "C:\Program Files\Python37\lib\site-packages\telegram\utils\request.py", line 325, in post
    body=json.dumps(data).encode('utf-8'),
  File "C:\Program Files\Python37\lib\json\__init__.py", line 231, in dumps
    return _default_encoder.encode(obj)
  File "C:\Program Files\Python37\lib\json\encoder.py", line 199, in encode
    chunks = self.iterencode(o, _one_shot=True)
  File "C:\Program Files\Python37\lib\json\encoder.py", line 257, in iterencode
    return _iterencode(o, 0)
  File "C:\Program Files\Python37\lib\json\encoder.py", line 179, in default
    raise TypeError(f'Object of type {o.__class__.__name__} '
TypeError: Object of type method is not JSON serializable
2019-09-07 19:02:06,887 - ERROR - No error handlers are registered, logging exception.
Traceback (most recent call last):
  File "C:\Program Files\Python37\lib\site-packages\telegram\ext\dispatcher.py", line 372, in process_update
    handler.handle_update(update, self, check, context)
  File "C:\Program Files\Python37\lib\site-packages\telegram\ext\handler.py", line 120, in handle_update
    return self.callback(dispatcher.bot, update, **optional_args)
  File "C:/Users/Philipesko/PycharmProjects/LearningPython14/megabot/bot.py", line 17, in talk_to_me
    update.message.reply_text(user_text)
  File "C:\Program Files\Python37\lib\site-packages\telegram\message.py", line 478, in reply_text
    return self.bot.send_message(self.chat_id, *args, **kwargs)
  File "C:\Program Files\Python37\lib\site-packages\telegram\bot.py", line 66, in decorator
    result = func(self, *args, **kwargs)
  File "C:\Program Files\Python37\lib\site-packages\telegram\bot.py", line 258, in send_message
    timeout=timeout, **kwargs)
  File "C:\Program Files\Python37\lib\site-packages\telegram\bot.py", line 123, in _message
    result = self._request.post(url, data, timeout=timeout)
  File "C:\Program Files\Python37\lib\site-packages\telegram\utils\request.py", line 325, in post
    body=json.dumps(data).encode('utf-8'),
  File "C:\Program Files\Python37\lib\json\__init__.py", line 231, in dumps
    return _default_encoder.encode(obj)
  File "C:\Program Files\Python37\lib\json\encoder.py", line 199, in encode
    chunks = self.iterencode(o, _one_shot=True)
  File "C:\Program Files\Python37\lib\json\encoder.py", line 257, in iterencode
    return _iterencode(o, 0)
  File "C:\Program Files\Python37\lib\json\encoder.py", line 179, in default
    raise TypeError(f'Object of type {o.__class__.__name__} '
TypeError: Object of type method is not JSON serializable
2019-09-07 19:02:36,832 - INFO - Send answer to the client
2019-09-07 19:02:38,893 - ERROR - No error handlers are registered, logging exception.
Traceback (most recent call last):
  File "C:\Program Files\Python37\lib\site-packages\telegram\ext\dispatcher.py", line 372, in process_update
    handler.handle_update(update, self, check, context)
  File "C:\Program Files\Python37\lib\site-packages\telegram\ext\handler.py", line 120, in handle_update
    return self.callback(dispatcher.bot, update, **optional_args)
  File "C:/Users/Philipesko/PycharmProjects/LearningPython14/megabot/bot.py", line 17, in talk_to_me
    update.message.reply_text(user_text)
  File "C:\Program Files\Python37\lib\site-packages\telegram\message.py", line 478, in reply_text
    return self.bot.send_message(self.chat_id, *args, **kwargs)
  File "C:\Program Files\Python37\lib\site-packages\telegram\bot.py", line 66, in decorator
    result = func(self, *args, **kwargs)
  File "C:\Program Files\Python37\lib\site-packages\telegram\bot.py", line 258, in send_message
    timeout=timeout, **kwargs)
  File "C:\Program Files\Python37\lib\site-packages\telegram\bot.py", line 123, in _message
    result = self._request.post(url, data, timeout=timeout)
  File "C:\Program Files\Python37\lib\site-packages\telegram\utils\request.py", line 325, in post
    body=json.dumps(data).encode('utf-8'),
  File "C:\Program Files\Python37\lib\json\__init__.py", line 231, in dumps
    return _default_encoder.encode(obj)
  File "C:\Program Files\Python37\lib\json\encoder.py", line 199, in encode
    chunks = self.iterencode(o, _one_shot=True)
  File "C:\Program Files\Python37\lib\json\encoder.py", line 257, in iterencode
    return _iterencode(o, 0)
  File "C:\Program Files\Python37\lib\json\encoder.py", line 179, in default
    raise TypeError(f'Object of type {o.__class__.__name__} '
TypeError: Object of type method is not JSON serializable
2019-09-07 19:03:24,076 - INFO - Бот запускается
2019-09-07 19:03:31,500 - INFO - Receive message text from client:привет
2019-09-07 19:03:35,355 - INFO - Send answer to the client
2019-09-07 19:06:06,872 - INFO - Бот запускается
2019-09-07 19:06:14,096 - INFO - Receive message text from client:привет.
<<<<<<< Updated upstream
=======
2019-09-08 17:02:33,379 - INFO - Send answer to the client
2019-09-08 17:02:34,051 - INFO - Send answer to the client
2019-09-08 17:02:34,864 - INFO - Send answer to the client
2019-09-08 17:02:36,074 - INFO - Receive message text from client:  a,sh
2019-09-08 17:03:11,484 - WARNING - Retrying (Retry(total=2, connect=None, read=None, redirect=None)) after connection broken by 'ConnectTimeoutError(<telegram.vendor.ptb_urllib3.urllib3.contrib.socks.SOCKSHTTPSConnection object at 0x000001759768C1C8>, 'Connection to api.telegram.org timed out. (connect timeout=5.0)')': /bot812960937:AAEXGUPi7Au90FxLNA0_Y947goTAzbXNS3A/getUpdates
2019-09-08 17:04:07,325 - ERROR - No error handlers are registered, logging exception.
Traceback (most recent call last):
  File "C:\Users\philippn\AppData\Local\Programs\Python\Python37\lib\site-packages\telegram\ext\dispatcher.py", line 372, in process_update
    handler.handle_update(update, self, check, context)
  File "C:\Users\philippn\AppData\Local\Programs\Python\Python37\lib\site-packages\telegram\ext\handler.py", line 117, in handle_update
    return self.callback(update, context)
  File "C:/Users/philippn/PycharmProjects/LearningPython14/megabot/bot.py", line 15, in talk_to_me
    user_text = update.message.text
AttributeError: 'CallbackContext' object has no attribute 'message'
2019-09-08 17:04:20,381 - ERROR - No error handlers are registered, logging exception.
Traceback (most recent call last):
  File "C:\Users\philippn\AppData\Local\Programs\Python\Python37\lib\site-packages\telegram\ext\dispatcher.py", line 372, in process_update
    handler.handle_update(update, self, check, context)
  File "C:\Users\philippn\AppData\Local\Programs\Python\Python37\lib\site-packages\telegram\ext\handler.py", line 117, in handle_update
    return self.callback(update, context)
  File "C:/Users/philippn/PycharmProjects/LearningPython14/megabot/bot.py", line 11, in greet_user
    update.message.reply_text(text)
AttributeError: 'CallbackContext' object has no attribute 'message'
2019-09-08 17:05:32,130 - ERROR - No error handlers are registered, logging exception.
Traceback (most recent call last):
  File "C:\Users\philippn\AppData\Local\Programs\Python\Python37\lib\site-packages\telegram\ext\dispatcher.py", line 372, in process_update
    handler.handle_update(update, self, check, context)
  File "C:\Users\philippn\AppData\Local\Programs\Python\Python37\lib\site-packages\telegram\ext\handler.py", line 117, in handle_update
    return self.callback(update, context)
  File "C:/Users/philippn/PycharmProjects/LearningPython14/megabot/bot.py", line 11, in greet_user
    update.message.reply_text(text)
AttributeError: 'CallbackContext' object has no attribute 'message'
2019-09-08 17:05:52,338 - ERROR - No error handlers are registered, logging exception.
Traceback (most recent call last):
  File "C:\Users\philippn\AppData\Local\Programs\Python\Python37\lib\site-packages\telegram\ext\dispatcher.py", line 372, in process_update
    handler.handle_update(update, self, check, context)
  File "C:\Users\philippn\AppData\Local\Programs\Python\Python37\lib\site-packages\telegram\ext\handler.py", line 117, in handle_update
    return self.callback(update, context)
  File "C:/Users/philippn/PycharmProjects/LearningPython14/megabot/bot.py", line 15, in talk_to_me
    user_text = update.message.text
AttributeError: 'CallbackContext' object has no attribute 'message'
2019-09-08 17:17:53,012 - ERROR - No error handlers are registered, logging exception.
Traceback (most recent call last):
  File "C:\Users\philippn\AppData\Local\Programs\Python\Python37\lib\site-packages\telegram\ext\dispatcher.py", line 372, in process_update
    handler.handle_update(update, self, check, context)
  File "C:\Users\philippn\AppData\Local\Programs\Python\Python37\lib\site-packages\telegram\ext\handler.py", line 117, in handle_update
    return self.callback(update, context)
  File "C:/Users/philippn/PycharmProjects/LearningPython14/megabot/bot.py", line 15, in talk_to_me
    user_text = update.message.text
AttributeError: 'CallbackContext' object has no attribute 'message'
2019-09-08 17:17:59,071 - ERROR - No error handlers are registered, logging exception.
Traceback (most recent call last):
  File "C:\Users\philippn\AppData\Local\Programs\Python\Python37\lib\site-packages\telegram\ext\dispatcher.py", line 372, in process_update
    handler.handle_update(update, self, check, context)
  File "C:\Users\philippn\AppData\Local\Programs\Python\Python37\lib\site-packages\telegram\ext\handler.py", line 117, in handle_update
    return self.callback(update, context)
  File "C:/Users/philippn/PycharmProjects/LearningPython14/megabot/bot.py", line 15, in talk_to_me
    user_text = update.message.text
AttributeError: 'CallbackContext' object has no attribute 'message'
2019-09-08 17:18:07,385 - ERROR - No error handlers are registered, logging exception.
Traceback (most recent call last):
  File "C:\Users\philippn\AppData\Local\Programs\Python\Python37\lib\site-packages\telegram\ext\dispatcher.py", line 372, in process_update
    handler.handle_update(update, self, check, context)
  File "C:\Users\philippn\AppData\Local\Programs\Python\Python37\lib\site-packages\telegram\ext\handler.py", line 117, in handle_update
    return self.callback(update, context)
  File "C:/Users/philippn/PycharmProjects/LearningPython14/megabot/bot.py", line 11, in greet_user
    update.message.reply_text(text)
AttributeError: 'CallbackContext' object has no attribute 'message'
2019-09-08 17:18:17,490 - ERROR - No error handlers are registered, logging exception.
Traceback (most recent call last):
  File "C:\Users\philippn\AppData\Local\Programs\Python\Python37\lib\site-packages\telegram\ext\dispatcher.py", line 372, in process_update
    handler.handle_update(update, self, check, context)
  File "C:\Users\philippn\AppData\Local\Programs\Python\Python37\lib\site-packages\telegram\ext\handler.py", line 117, in handle_update
    return self.callback(update, context)
  File "C:/Users/philippn/PycharmProjects/LearningPython14/megabot/bot.py", line 15, in talk_to_me
    user_text = update.message.text
AttributeError: 'CallbackContext' object has no attribute 'message'
2019-09-08 17:18:26,027 - ERROR - No error handlers are registered, logging exception.
Traceback (most recent call last):
  File "C:\Users\philippn\AppData\Local\Programs\Python\Python37\lib\site-packages\telegram\ext\dispatcher.py", line 372, in process_update
    handler.handle_update(update, self, check, context)
  File "C:\Users\philippn\AppData\Local\Programs\Python\Python37\lib\site-packages\telegram\ext\handler.py", line 117, in handle_update
    return self.callback(update, context)
  File "C:/Users/philippn/PycharmProjects/LearningPython14/megabot/bot.py", line 11, in greet_user
    update.message.reply_text(text)
AttributeError: 'CallbackContext' object has no attribute 'message'
>>>>>>> Stashed changes
2019-09-12 14:16:41,837 - INFO - Send answer to the client
2019-09-12 14:16:48,001 - ERROR - No error handlers are registered, logging exception.
Traceback (most recent call last):
  File "C:\Users\philippn\AppData\Local\Programs\Python\Python37\lib\site-packages\telegram\ext\dispatcher.py", line 372, in process_update
    handler.handle_update(update, self, check, context)
  File "C:\Users\philippn\AppData\Local\Programs\Python\Python37\lib\site-packages\telegram\ext\handler.py", line 120, in handle_update
    return self.callback(dispatcher.bot, update, **optional_args)
  File "C:/Users/philippn/PycharmProjects/LearningPython14/megabot/bot.py", line 11, in greet_planet
    planet = getattr(ephem, attribute_planet_name)(datetime.now())
AttributeError: module 'ephem' has no attribute '/planet'
2019-09-12 14:16:51,294 - INFO - Receive message text from client:  Mars
2019-09-12 14:18:00,307 - ERROR - No error handlers are registered, logging exception.
Traceback (most recent call last):
  File "C:\Users\philippn\AppData\Local\Programs\Python\Python37\lib\site-packages\telegram\ext\dispatcher.py", line 372, in process_update
    handler.handle_update(update, self, check, context)
  File "C:\Users\philippn\AppData\Local\Programs\Python\Python37\lib\site-packages\telegram\ext\handler.py", line 120, in handle_update
    return self.callback(dispatcher.bot, update, **optional_args)
  File "C:/Users/philippn/PycharmProjects/LearningPython14/megabot/bot.py", line 11, in greet_planet
    planet = getattr(ephem, attribute_planet_name)(datetime.now())
AttributeError: module 'ephem' has no attribute '/planet'
2019-09-12 14:18:05,790 - INFO - Receive message text from client:  Mars
2019-09-12 14:20:00,206 - ERROR - No error handlers are registered, logging exception.
Traceback (most recent call last):
  File "C:\Users\philippn\AppData\Local\Programs\Python\Python37\lib\site-packages\telegram\ext\dispatcher.py", line 372, in process_update
    handler.handle_update(update, self, check, context)
  File "C:\Users\philippn\AppData\Local\Programs\Python\Python37\lib\site-packages\telegram\ext\handler.py", line 120, in handle_update
    return self.callback(dispatcher.bot, update, **optional_args)
  File "C:/Users/philippn/PycharmProjects/LearningPython14/megabot/bot.py", line 11, in greet_planet
    planet = getattr(ephem, attribute_planet_name)(datetime.now())
AttributeError: module 'ephem' has no attribute '/planet'
2019-09-12 14:20:04,237 - INFO - Receive message text from client:  Mars
2019-09-12 14:25:37,521 - ERROR - No error handlers are registered, logging exception.
Traceback (most recent call last):
  File "C:\Users\philippn\AppData\Local\Programs\Python\Python37\lib\site-packages\telegram\ext\dispatcher.py", line 372, in process_update
    handler.handle_update(update, self, check, context)
  File "C:\Users\philippn\AppData\Local\Programs\Python\Python37\lib\site-packages\telegram\ext\handler.py", line 120, in handle_update
    return self.callback(dispatcher.bot, update, **optional_args)
  File "C:/Users/philippn/PycharmProjects/LearningPython14/megabot/bot.py", line 11, in greet_planet
    planet = getattr(ephem, arrt_planet_name(1))(datetime.now())
TypeError: 'list' object is not callable
2019-09-12 14:25:56,870 - ERROR - No error handlers are registered, logging exception.
Traceback (most recent call last):
  File "C:\Users\philippn\AppData\Local\Programs\Python\Python37\lib\site-packages\telegram\ext\dispatcher.py", line 372, in process_update
    handler.handle_update(update, self, check, context)
  File "C:\Users\philippn\AppData\Local\Programs\Python\Python37\lib\site-packages\telegram\ext\handler.py", line 120, in handle_update
    return self.callback(dispatcher.bot, update, **optional_args)
  File "C:/Users/philippn/PycharmProjects/LearningPython14/megabot/bot.py", line 11, in greet_planet
    planet = getattr(ephem, arrt_planet_name(1))(datetime.now())
TypeError: 'list' object is not callable
2019-09-12 14:26:52,075 - ERROR - No error handlers are registered, logging exception.
Traceback (most recent call last):
  File "C:\Users\philippn\AppData\Local\Programs\Python\Python37\lib\site-packages\telegram\ext\dispatcher.py", line 372, in process_update
    handler.handle_update(update, self, check, context)
  File "C:\Users\philippn\AppData\Local\Programs\Python\Python37\lib\site-packages\telegram\ext\handler.py", line 120, in handle_update
    return self.callback(dispatcher.bot, update, **optional_args)
  File "C:/Users/philippn/PycharmProjects/LearningPython14/megabot/bot.py", line 11, in greet_planet
    planet = getattr(ephem, arrt_planet_name(1))(datetime.now())
TypeError: 'list' object is not callable
2019-09-12 14:26:56,631 - INFO - Receive message text from client:  asd
2019-09-12 17:50:03,191 - ERROR - No error handlers are registered, logging exception.
Traceback (most recent call last):
  File "C:\Users\philippn\AppData\Local\Programs\Python\Python37\lib\site-packages\telegram\ext\dispatcher.py", line 372, in process_update
    handler.handle_update(update, self, check, context)
  File "C:\Users\philippn\AppData\Local\Programs\Python\Python37\lib\site-packages\telegram\ext\handler.py", line 120, in handle_update
    return self.callback(dispatcher.bot, update, **optional_args)
  File "C:/Users/philippn/PycharmProjects/LearningPython14/megabot/bot.py", line 23, in greet_planet
    mybot.planets(bot, update)
NameError: name 'mybot' is not defined
2019-09-12 17:50:06,659 - INFO - Receive message text from client:  Mars
2019-09-12 17:51:22,712 - ERROR - No error handlers are registered, logging exception.
Traceback (most recent call last):
  File "C:\Users\philippn\AppData\Local\Programs\Python\Python37\lib\site-packages\telegram\ext\dispatcher.py", line 372, in process_update
    handler.handle_update(update, self, check, context)
  File "C:\Users\philippn\AppData\Local\Programs\Python\Python37\lib\site-packages\telegram\ext\handler.py", line 120, in handle_update
    return self.callback(dispatcher.bot, update, **optional_args)
  File "C:/Users/philippn/PycharmProjects/LearningPython14/megabot/bot.py", line 23, in greet_planet
    update.planets(bot, update)
AttributeError: 'Update' object has no attribute 'planets'
2019-09-12 17:51:26,819 - INFO - Receive message text from client:  Mars
2019-09-12 20:04:31,340 - INFO - Receive message text from client:  Mars
2019-09-12 20:04:42,266 - ERROR - No error handlers are registered, logging exception.
Traceback (most recent call last):
  File "C:\Users\philippn\AppData\Local\Programs\Python\Python37\lib\site-packages\telegram\ext\dispatcher.py", line 372, in process_update
    handler.handle_update(update, self, check, context)
  File "C:\Users\philippn\AppData\Local\Programs\Python\Python37\lib\site-packages\telegram\ext\handler.py", line 120, in handle_update
    return self.callback(dispatcher.bot, update, **optional_args)
  File "C:/Users/philippn/PycharmProjects/LearningPython14/megabot/bot.py", line 11, in greet_planet
    update.planets(bot, update)
AttributeError: 'Update' object has no attribute 'planets'
2019-09-12 20:04:45,689 - INFO - Receive message text from client:  Mars
2019-09-12 20:06:36,306 - ERROR - No error handlers are registered, logging exception.
Traceback (most recent call last):
  File "C:\Users\philippn\AppData\Local\Programs\Python\Python37\lib\site-packages\telegram\ext\dispatcher.py", line 372, in process_update
    handler.handle_update(update, self, check, context)
  File "C:\Users\philippn\AppData\Local\Programs\Python\Python37\lib\site-packages\telegram\ext\handler.py", line 120, in handle_update
    return self.callback(dispatcher.bot, update, **optional_args)
  File "C:/Users/philippn/PycharmProjects/LearningPython14/megabot/bot.py", line 11, in greet_planet
    update.planets(bot, update)
AttributeError: 'Update' object has no attribute 'planets'
2019-09-12 20:06:39,339 - INFO - Receive message text from client:  Mars
2019-09-12 20:09:04,668 - ERROR - No error handlers are registered, logging exception.
Traceback (most recent call last):
  File "C:\Users\philippn\AppData\Local\Programs\Python\Python37\lib\site-packages\telegram\ext\dispatcher.py", line 372, in process_update
    handler.handle_update(update, self, check, context)
  File "C:\Users\philippn\AppData\Local\Programs\Python\Python37\lib\site-packages\telegram\ext\handler.py", line 120, in handle_update
    return self.callback(dispatcher.bot, update, **optional_args)
  File "C:/Users/philippn/PycharmProjects/LearningPython14/megabot/bot.py", line 11, in greet_planet
    update.planets(bot, update)
AttributeError: 'Update' object has no attribute 'planets'
2019-09-12 20:09:07,415 - INFO - Receive message text from client:  Mars
2019-09-12 20:10:43,971 - ERROR - No error handlers are registered, logging exception.
Traceback (most recent call last):
  File "C:\Users\philippn\AppData\Local\Programs\Python\Python37\lib\site-packages\telegram\ext\dispatcher.py", line 372, in process_update
    handler.handle_update(update, self, check, context)
  File "C:\Users\philippn\AppData\Local\Programs\Python\Python37\lib\site-packages\telegram\ext\handler.py", line 120, in handle_update
    return self.callback(dispatcher.bot, update, **optional_args)
  File "C:/Users/philippn/PycharmProjects/LearningPython14/megabot/bot.py", line 11, in greet_planet
    update.planets(bot, update)
AttributeError: 'Update' object has no attribute 'planets'
2019-09-12 20:10:46,367 - INFO - Receive message text from client:  Mars
2019-09-12 20:29:13,567 - ERROR - No error handlers are registered, logging exception.
Traceback (most recent call last):
  File "C:\Users\philippn\AppData\Local\Programs\Python\Python37\lib\site-packages\telegram\ext\dispatcher.py", line 372, in process_update
    handler.handle_update(update, self, check, context)
  File "C:\Users\philippn\AppData\Local\Programs\Python\Python37\lib\site-packages\telegram\ext\handler.py", line 120, in handle_update
    return self.callback(dispatcher.bot, update, **optional_args)
  File "C:/Users/philippn/PycharmProjects/LearningPython14/megabot/bot.py", line 14, in greet_planet
    planet = getattr(ephem, arrt_planet_name[1])(datetime.now())
IndexError: list index out of range
2019-09-12 20:29:19,430 - INFO - Receive message text from client:  Mars
2019-09-14 13:10:34,006 - ERROR - No error handlers are registered, logging exception.
Traceback (most recent call last):
  File "C:\Users\philippn\AppData\Local\Programs\Python\Python37\lib\site-packages\telegram\ext\dispatcher.py", line 372, in process_update
    handler.handle_update(update, self, check, context)
  File "C:\Users\philippn\AppData\Local\Programs\Python\Python37\lib\site-packages\telegram\ext\handler.py", line 120, in handle_update
    return self.callback(dispatcher.bot, update, **optional_args)
  File "C:/Users/philippn/PycharmProjects/LearningPython14/megabot/bot.py", line 13, in greet_planet
    planet = getattr(ephem, arrt_planet_name[1])(datetime.now())
IndexError: list index out of range
2019-09-14 13:10:43,427 - INFO - Receive message text from client:  test
2019-09-14 13:23:58,172 - INFO - Received signal 2 (SIGINT), stopping...
2019-09-14 20:27:53,219 - WARNING - Retrying (Retry(total=2, connect=None, read=None, redirect=None)) after connection broken by 'NewConnectionError('<telegram.vendor.ptb_urllib3.urllib3.contrib.socks.SOCKSHTTPSConnection object at 0x0000022508097E88>: Failed to establish a new connection: 0x02: Connection not allowed by ruleset')': /bot812960937:AAGPMxogcN_DkjSGtXLdWg6RkTPLMwtDOYU/getMe
2019-09-14 20:27:53,586 - WARNING - Retrying (Retry(total=1, connect=None, read=None, redirect=None)) after connection broken by 'NewConnectionError('<telegram.vendor.ptb_urllib3.urllib3.contrib.socks.SOCKSHTTPSConnection object at 0x00000225080B0508>: Failed to establish a new connection: 0x02: Connection not allowed by ruleset')': /bot812960937:AAGPMxogcN_DkjSGtXLdWg6RkTPLMwtDOYU/getMe
2019-09-14 20:27:53,970 - WARNING - Retrying (Retry(total=0, connect=None, read=None, redirect=None)) after connection broken by 'NewConnectionError('<telegram.vendor.ptb_urllib3.urllib3.contrib.socks.SOCKSHTTPSConnection object at 0x00000225080B0688>: Failed to establish a new connection: 0x02: Connection not allowed by ruleset')': /bot812960937:AAGPMxogcN_DkjSGtXLdWg6RkTPLMwtDOYU/getMe
2019-09-14 20:29:05,382 - ERROR - No error handlers are registered, logging exception.
Traceback (most recent call last):
  File "C:\Users\philippn\AppData\Local\Programs\Python\Python37\lib\site-packages\telegram\ext\dispatcher.py", line 372, in process_update
    handler.handle_update(update, self, check, context)
  File "C:\Users\philippn\AppData\Local\Programs\Python\Python37\lib\site-packages\telegram\ext\handler.py", line 120, in handle_update
    return self.callback(dispatcher.bot, update, **optional_args)
  File "C:/Users/philippn/PycharmProjects/LearningPython14/megabot/bot.py", line 50, in talk_to_me
    logging.info(f"User: {update.message.chat.first_name}, Chat id: {update.message.chat.id}, Message: {update.message.chat.text} ")
AttributeError: 'Chat' object has no attribute 'text'
2019-09-14 20:29:05,384 - ERROR - No error handlers are registered, logging exception.
Traceback (most recent call last):
  File "C:\Users\philippn\AppData\Local\Programs\Python\Python37\lib\site-packages\telegram\ext\dispatcher.py", line 372, in process_update
    handler.handle_update(update, self, check, context)
  File "C:\Users\philippn\AppData\Local\Programs\Python\Python37\lib\site-packages\telegram\ext\handler.py", line 120, in handle_update
    return self.callback(dispatcher.bot, update, **optional_args)
  File "C:/Users/philippn/PycharmProjects/LearningPython14/megabot/bot.py", line 50, in talk_to_me
    logging.info(f"User: {update.message.chat.first_name}, Chat id: {update.message.chat.id}, Message: {update.message.chat.text} ")
AttributeError: 'Chat' object has no attribute 'text'
2019-09-14 20:29:14,880 - ERROR - No error handlers are registered, logging exception.
Traceback (most recent call last):
  File "C:\Users\philippn\AppData\Local\Programs\Python\Python37\lib\site-packages\telegram\ext\dispatcher.py", line 372, in process_update
    handler.handle_update(update, self, check, context)
  File "C:\Users\philippn\AppData\Local\Programs\Python\Python37\lib\site-packages\telegram\ext\handler.py", line 120, in handle_update
    return self.callback(dispatcher.bot, update, **optional_args)
  File "C:/Users/philippn/PycharmProjects/LearningPython14/megabot/bot.py", line 50, in talk_to_me
    logging.info(f"User: {update.message.chat.first_name}, Chat id: {update.message.chat.id}, Message: {update.message.chat.text} ")
AttributeError: 'Chat' object has no attribute 'text'
2019-09-14 20:29:33,643 - ERROR - No error handlers are registered, logging exception.
Traceback (most recent call last):
  File "C:\Users\philippn\AppData\Local\Programs\Python\Python37\lib\site-packages\telegram\ext\dispatcher.py", line 372, in process_update
    handler.handle_update(update, self, check, context)
  File "C:\Users\philippn\AppData\Local\Programs\Python\Python37\lib\site-packages\telegram\ext\handler.py", line 120, in handle_update
    return self.callback(dispatcher.bot, update, **optional_args)
  File "C:/Users/philippn/PycharmProjects/LearningPython14/megabot/bot.py", line 50, in talk_to_me
    logging.info(f"User: {update.message.chat.first_name}, Chat id: {update.message.chat.id}, Message: {update.message.chat.text} ")
AttributeError: 'Chat' object has no attribute 'text'
2019-09-14 20:29:35,678 - ERROR - No error handlers are registered, logging exception.
Traceback (most recent call last):
  File "C:\Users\philippn\AppData\Local\Programs\Python\Python37\lib\site-packages\telegram\ext\dispatcher.py", line 372, in process_update
    handler.handle_update(update, self, check, context)
  File "C:\Users\philippn\AppData\Local\Programs\Python\Python37\lib\site-packages\telegram\ext\handler.py", line 120, in handle_update
    return self.callback(dispatcher.bot, update, **optional_args)
  File "C:/Users/philippn/PycharmProjects/LearningPython14/megabot/bot.py", line 50, in talk_to_me
    logging.info(f"User: {update.message.chat.first_name}, Chat id: {update.message.chat.id}, Message: {update.message.chat.text} ")
AttributeError: 'Chat' object has no attribute 'text'
2019-09-14 20:33:51,262 - ERROR - No error handlers are registered, logging exception.
Traceback (most recent call last):
  File "C:\Users\philippn\AppData\Local\Programs\Python\Python37\lib\site-packages\telegram\ext\dispatcher.py", line 372, in process_update
    handler.handle_update(update, self, check, context)
  File "C:\Users\philippn\AppData\Local\Programs\Python\Python37\lib\site-packages\telegram\ext\handler.py", line 117, in handle_update
    return self.callback(update, context)
  File "C:/Users/philippn/PycharmProjects/LearningPython14/megabot/bot.py", line 51, in talk_to_me
    reply_text_for_user = f"Hello {update.message.chat.first_name}, you wrote next message: {update.message.chat.text}"
AttributeError: 'CallbackContext' object has no attribute 'message'
2019-09-14 20:33:56,788 - ERROR - No error handlers are registered, logging exception.
Traceback (most recent call last):
  File "C:\Users\philippn\AppData\Local\Programs\Python\Python37\lib\site-packages\telegram\ext\dispatcher.py", line 372, in process_update
    handler.handle_update(update, self, check, context)
  File "C:\Users\philippn\AppData\Local\Programs\Python\Python37\lib\site-packages\telegram\ext\handler.py", line 117, in handle_update
    return self.callback(update, context)
  File "C:/Users/philippn/PycharmProjects/LearningPython14/megabot/bot.py", line 41, in greet_user
    update.message.reply_text(text)
AttributeError: 'CallbackContext' object has no attribute 'message'
2019-09-14 20:34:03,624 - ERROR - No error handlers are registered, logging exception.
Traceback (most recent call last):
  File "C:\Users\philippn\AppData\Local\Programs\Python\Python37\lib\site-packages\telegram\ext\dispatcher.py", line 372, in process_update
    handler.handle_update(update, self, check, context)
  File "C:\Users\philippn\AppData\Local\Programs\Python\Python37\lib\site-packages\telegram\ext\handler.py", line 117, in handle_update
    return self.callback(update, context)
  File "C:/Users/philippn/PycharmProjects/LearningPython14/megabot/bot.py", line 51, in talk_to_me
    reply_text_for_user = f"Hello {update.message.chat.first_name}, you wrote next message: {update.message.chat.text}"
AttributeError: 'CallbackContext' object has no attribute 'message'
2019-09-14 20:34:36,991 - ERROR - No error handlers are registered, logging exception.
Traceback (most recent call last):
  File "C:\Users\philippn\AppData\Local\Programs\Python\Python37\lib\site-packages\telegram\ext\dispatcher.py", line 372, in process_update
    handler.handle_update(update, self, check, context)
  File "C:\Users\philippn\AppData\Local\Programs\Python\Python37\lib\site-packages\telegram\ext\handler.py", line 117, in handle_update
    return self.callback(update, context)
  File "C:/Users/philippn/PycharmProjects/LearningPython14/megabot/bot.py", line 51, in talk_to_me
    reply_text_for_user = f"Hello {update.message.chat.first_name}, you wrote next message: {update.message.chat.text}"
AttributeError: 'CallbackContext' object has no attribute 'message'
2019-09-14 20:34:43,959 - ERROR - No error handlers are registered, logging exception.
Traceback (most recent call last):
  File "C:\Users\philippn\AppData\Local\Programs\Python\Python37\lib\site-packages\telegram\ext\dispatcher.py", line 372, in process_update
    handler.handle_update(update, self, check, context)
  File "C:\Users\philippn\AppData\Local\Programs\Python\Python37\lib\site-packages\telegram\ext\handler.py", line 117, in handle_update
    return self.callback(update, context)
  File "C:/Users/philippn/PycharmProjects/LearningPython14/megabot/bot.py", line 41, in greet_user
    update.message.reply_text(text)
AttributeError: 'CallbackContext' object has no attribute 'message'
2019-09-14 20:35:08,121 - ERROR - No error handlers are registered, logging exception.
Traceback (most recent call last):
  File "C:\Users\philippn\AppData\Local\Programs\Python\Python37\lib\site-packages\telegram\ext\dispatcher.py", line 372, in process_update
    handler.handle_update(update, self, check, context)
  File "C:\Users\philippn\AppData\Local\Programs\Python\Python37\lib\site-packages\telegram\ext\handler.py", line 120, in handle_update
    return self.callback(dispatcher.bot, update, **optional_args)
  File "C:/Users/philippn/PycharmProjects/LearningPython14/megabot/bot.py", line 51, in talk_to_me
    reply_text_for_user = f"Hello {update.message.chat.first_name}, you wrote next message: {update.message.chat.text}"
AttributeError: 'Chat' object has no attribute 'text'
2019-09-14 20:35:14,565 - ERROR - No error handlers are registered, logging exception.
Traceback (most recent call last):
  File "C:\Users\philippn\AppData\Local\Programs\Python\Python37\lib\site-packages\telegram\ext\dispatcher.py", line 372, in process_update
    handler.handle_update(update, self, check, context)
  File "C:\Users\philippn\AppData\Local\Programs\Python\Python37\lib\site-packages\telegram\ext\handler.py", line 120, in handle_update
    return self.callback(dispatcher.bot, update, **optional_args)
  File "C:/Users/philippn/PycharmProjects/LearningPython14/megabot/bot.py", line 51, in talk_to_me
    reply_text_for_user = f"Hello {update.message.chat.first_name}, you wrote next message: {update.message.chat.text}"
AttributeError: 'Chat' object has no attribute 'text'
2019-09-14 20:35:18,265 - INFO - Send answer to the client
2019-09-14 20:36:38,815 - ERROR - No error handlers are registered, logging exception.
Traceback (most recent call last):
  File "C:\Users\philippn\AppData\Local\Programs\Python\Python37\lib\site-packages\telegram\ext\dispatcher.py", line 372, in process_update
    handler.handle_update(update, self, check, context)
  File "C:\Users\philippn\AppData\Local\Programs\Python\Python37\lib\site-packages\telegram\ext\handler.py", line 120, in handle_update
    return self.callback(dispatcher.bot, update, **optional_args)
  File "C:/Users/philippn/PycharmProjects/LearningPython14/megabot/bot.py", line 51, in talk_to_me
    reply_text_for_user = f"Hello {update.message.chat.first_name}, you wrote next message: {update.message.chat.text}"
AttributeError: 'Chat' object has no attribute 'text'
2019-09-14 20:38:05,483 - INFO - User: Nikita, Chat id: 276693710, Message: where my messages? 
2019-09-14 20:38:11,355 - INFO - User: Nikita, Chat id: 276693710, Message: Yes 
2019-09-14 20:38:14,880 - INFO - User: Nikita, Chat id: 276693710, Message: beatch 
2019-09-14 20:38:26,247 - INFO - User: Nikita, Chat id: 276693710, Message: give me my /minion 
2019-09-14 20:57:36,735 - INFO - User: Nikita, Chat id: 276693710, Message: Hello 
2019-09-14 21:04:02,531 - INFO - User: Nikita, Chat id: 276693710, Message: hi 
2019-09-14 21:04:14,559 - INFO - User: Nikita, Chat id: 276693710, Message: iiha 
2019-09-14 21:31:22,698 - ERROR - No error handlers are registered, logging exception.
Traceback (most recent call last):
  File "C:\Users\philippn\AppData\Local\Programs\Python\Python37\lib\site-packages\telegram\ext\dispatcher.py", line 372, in process_update
    handler.handle_update(update, self, check, context)
  File "C:\Users\philippn\AppData\Local\Programs\Python\Python37\lib\site-packages\telegram\ext\handler.py", line 120, in handle_update
    return self.callback(dispatcher.bot, update, **optional_args)
  File "C:/Users/philippn/PycharmProjects/LearningPython14/megabot/bot.py", line 50, in greet_user
    [contact_button, location_button]
TypeError: list indices must be integers or slices, not tuple
2019-09-14 21:31:35,152 - ERROR - No error handlers are registered, logging exception.
Traceback (most recent call last):
  File "C:\Users\philippn\AppData\Local\Programs\Python\Python37\lib\site-packages\telegram\ext\dispatcher.py", line 372, in process_update
    handler.handle_update(update, self, check, context)
  File "C:\Users\philippn\AppData\Local\Programs\Python\Python37\lib\site-packages\telegram\ext\handler.py", line 120, in handle_update
    return self.callback(dispatcher.bot, update, **optional_args)
  File "C:/Users/philippn/PycharmProjects/LearningPython14/megabot/bot.py", line 50, in greet_user
    [contact_button, location_button]
TypeError: list indices must be integers or slices, not tuple
2019-09-14 21:40:52,883 - ERROR - No error handlers are registered, logging exception.
Traceback (most recent call last):
  File "C:\Users\philippn\AppData\Local\Programs\Python\Python37\lib\site-packages\telegram\ext\dispatcher.py", line 372, in process_update
    handler.handle_update(update, self, check, context)
  File "C:\Users\philippn\AppData\Local\Programs\Python\Python37\lib\site-packages\telegram\ext\handler.py", line 120, in handle_update
    return self.callback(dispatcher.bot, update, **optional_args)
  File "C:/Users/philippn/PycharmProjects/LearningPython14/megabot/bot.py", line 73, in get_contact
    update.message.reply_text(f"Thanks! {change_avatar(user_data)}")
TypeError: change_avatar() missing 2 required positional arguments: 'update' and 'user_data'
2019-09-14 21:41:17,678 - ERROR - No error handlers are registered, logging exception.
Traceback (most recent call last):
  File "C:\Users\philippn\AppData\Local\Programs\Python\Python37\lib\site-packages\telegram\ext\dispatcher.py", line 372, in process_update
    handler.handle_update(update, self, check, context)
  File "C:\Users\philippn\AppData\Local\Programs\Python\Python37\lib\site-packages\telegram\ext\handler.py", line 120, in handle_update
    return self.callback(dispatcher.bot, update, **optional_args)
  File "C:/Users/philippn/PycharmProjects/LearningPython14/megabot/bot.py", line 73, in get_contact
    update.message.reply_text(f"Thanks! {change_avatar(user_data)}")
TypeError: change_avatar() missing 2 required positional arguments: 'update' and 'user_data'
2019-09-14 21:42:34,021 - ERROR - No error handlers are registered, logging exception.
Traceback (most recent call last):
  File "C:\Users\philippn\AppData\Local\Programs\Python\Python37\lib\site-packages\telegram\ext\dispatcher.py", line 372, in process_update
    handler.handle_update(update, self, check, context)
  File "C:\Users\philippn\AppData\Local\Programs\Python\Python37\lib\site-packages\telegram\ext\handler.py", line 120, in handle_update
    return self.callback(dispatcher.bot, update, **optional_args)
  File "C:/Users/philippn/PycharmProjects/LearningPython14/megabot/bot.py", line 73, in get_contact
    update.message.reply_text(f"Thanks! {change_avatar(user_data)}")
TypeError: change_avatar() missing 2 required positional arguments: 'update' and 'user_data'
2019-09-14 21:53:31,497 - INFO - User: Nikita, Chat id: 276693710, Message: HI 
2019-09-14 21:54:42,598 - INFO - User: Nikita, Chat id: 276693710, Message: Hi 
2019-09-14 21:55:10,347 - INFO - User: Nikita, Chat id: 276693710, Message: Hi 
2019-09-14 21:56:34,210 - INFO - User: Nikita, Chat id: 276693710, Message: hi 
